Workbook

Sheet 📖 Guide
A2: 📖 Workbook Guide — What everything means and how to use it
A4: Sheets in this workbook: 📖 Guide → 📋 MasterData → 📅 Monthly Summary → 📊 Dashboard → 🔧 Lists
A6: 📋 MasterData — every transaction you've logged, one row per entry
B7: Column | C7: What it stores | E7: Example value
B8: Date | C8: The calendar date of the transaction. Update this to the real day when you log it. | E8: e.g. 2026-05-14 (not just month start)
B9: Year | C9: The year. Used by Dashboard filters. Picked automatically from Date — don't edit. | E9: e.g. 2026
B10: Month | C10: 3-letter month abbreviation. Used by Dashboard filters. Don't edit. | E10: e.g. May
B11: Value | C11: Amount in PLN (always positive). For expenses, income, and savings alike. | E11: e.g. 3 200 (never negative)
B12: Type | C12: One of three choices: • Expense — money going out • Income — money coming in • Savings — money moved to savings | E12: Expense / Income / Savings
B13: Category | C13: What the money was spent on. Pick from the dropdown — don't type freehand. See the Lists sheet for all options. | E13: e.g. Housing, Groceries, Children
B14: Person | C14: Who the expense was for. Leave blank if it's a household expense. Only fill in when it's clearly for one person. | E14: e.g. Alice, Bob, Carol, Dave
B15: Description | C15: Free text note about the transaction. Keep it short — 3-6 words is enough. | E15: e.g. "Petrol", "VW insurance 3 months"
B16: IsRecurring | C16: TRUE = same expense every month (rent, loan, internet). FALSE = one-off purchase. Helps split fixed vs variable costs in reports. | E16: TRUE for rent, FALSE for a camera
B17: IsDone | C17: TRUE = transaction is confirmed and real. FALSE = planned/pending — excluded from totals. Leave TRUE for everything you've already paid. | E17: TRUE (FALSE only for future planned items)
B18: Currency | C18: Which currency this transaction was made in. Default: PLN. Change to EUR, USD, etc. for foreign transactions. Set the exchange rate in the Lists sheet (col G-H). | E18: PLN (default) or EUR for a trip expense
A21: 📅 Monthly Summary — one row per month, auto-calculated from MasterData
B22: Column | C22: What it shows | E22: Example value
B23: Year / Month | C23: Identifies the period. One row = one calendar month. | E23: 2025 / Nov
B24: Income | C24: Total of all Income-type rows for that month. | E24: 10 000 PLN (your salary + any extras)
B25: Expenses | C25: Total of all Expense-type rows for that month. | E25: 8 000 PLN
B26: Savings | C26: Total of all Savings-type rows for that month. | E26: 1 000 PLN
B27: Net | C27: Income − Expenses − Savings. Should be 0 if everything is logged correctly. Positive = unlogged income. Negative = unlogged expense. | E27: −52 PLN (small rounding gap — fine)
A30: 📊 Dashboard — change B2 (Year) and D2 (Month) to filter everything
B31: Section / Field | C31: What it does | E31: Example / tip
B32: B2 — Year filter | C32: Type or pick the year you want to view. All period totals and category table update instantly. | E32: Change to 2025 → all figures switch to 2025
B33: D2 — Month filter | C33: Pick a month to see that month only. Leave blank (delete the value) to see the whole year. | E33: Delete 'May' → shows full year 2026
B34: F2 — Display Currency | C34: Pick any currency — all Dashboard numbers convert instantly. PLN = default (no conversion). Switch to EUR, AZN, etc. to see everything in that currency using the rate from Lists sheet. | E34: Change to AZN → income shows as ~1 500 EUR instead of 6 500 PLN
B35: All-Time Totals (row 6) | C35: Income / Expenses / Savings since you started tracking. Ignores the Year/Month filter — always shows everything. | E35: Total income logged: 250 000 PLN (example total)
B36: Selected Period (rows 10–15) | C36: Income, Expenses, Savings for the chosen Year+Month. Net = Income − Expenses − Savings (should be near 0). Savings Rate = Savings ÷ Income. | E36: May 2026: Income 12 000, Expenses 7 000, Savings 5 000
B37: ⚠ Check row | C37: Tells you if the numbers don't add up. '✓ Balanced' = good. Any other message = a transaction is missing or double-counted. | E37: 'Overreported: 194 PLN' → find the duplicate
A38: Budget vs Actual table (H–L)
A41: 🔧 Lists — the reference data that powers all dropdowns
B42: Column | C42: What it controls | E42: How to update
B43: Months (col A) | C43: The 12 month abbreviations used in MasterData Month column and Dashboard filter. | E43: Don't edit — these must stay Jan..Dec
B44: TxnTypes (col B) | C44: The three transaction types: Expense, Income, Savings. Used by the Type dropdown in MasterData. | E44: Don't edit — the formulas depend on exact spelling
B45: Categories (col C) | C45: All spending categories available in the MasterData Category dropdown. Add a new row here to add a new category everywhere. | E45: To add 'Pet care': type it in C19, then update Dashboard budget table
A46: Persons (col D)
A49: 💡 Quick Tips
B50: Adding a new transaction | C50: Go to MasterData → scroll to the bottom → fill in the next empty row. Use the dropdowns for Type, Category, and Person — don't type freehand. | E50: Set Date to the real day, not just the 1st of month
A51: Changing your monthly budget
...

Sheet Lists
A1: Months | B1: TxnTypes | C1: Categories | D1: Budget (base) | E1: Persons | F1: Years | H1: Currency | I1: Rate to base | M1: Goal Name | N1: Alloc % | O1: Goal (PLN)
A2: Jan | B2: Expense | C2: Groceries | E2: Person 1 | F2: 2024 | H2: PLN | I2: 1 | M2: House | N2: 0.6 | O2: 0
A3: Feb | B3: Income | C3: Housing | E3: Person 2 | F3: 2025 | H3: EUR | I3: 4.28 | M3: Rainy Day | N3: 0.3 | O3: 0
A4: Mar | B4: Savings | C4: Transport | F4: 2026 | H4: USD | I4: 3.92 | M4: Other | N4: 0.1 | O4: 0
A5: Apr | C5: Utilities | F5: 2027 | H5: GBP | I5: 4.98
A6: May | C6: Healthcare | H6: AZN | I6: 2.51
A7: Jun | C7: Entertainment | H7: CHF | I7: 4.41
A8: Jul | C8: Travel | H8: ← edit blue rates
A9: Aug | C9: Children
A10: Sep | C10: Personal
A11: Oct | C11: Shopping
A12: Nov | C12: Insurance
A13: Dec | C13: Loan
C14: Investment
C15: Government
C16: Education
C17: Subscriptions
C18: Other

Sheet MasterData
A1: Date | B1: Year | C1: Month | D1: Value | E1: Type | F1: Category | G1: Person | H1: Description | I1: IsRecurring | J1: IsDone | K1: Currency | L1: Value (base)

Sheet Monthly Summary
A1: Year | B1: Month | C1: Income | D1: Expenses | E1: Savings | F1: Net | G1: Savings Rate %

Sheet Dashboard
A1: ⚙ Filter
A2: Year | B2: 2026 | C2: Month | E2: Display | F2: PLN | N2: =IFERROR(VLOOKUP($F$2,Lists!$H$2:$I$1048576,2,0),1)
A4: 📊 All-Time Totals
B5: Income | C5: Expenses | D5: Savings | E5: Net Worth
B6: =(SUMIFS(MasterData!$L$2:$L$1048576,MasterData!$E$2:$E$1048576,"Income",MasterData!$J$2:$J$1048576,TRUE))/($N$2) | C6: =(SUMIFS(MasterData!$L$2:$L$1048576,MasterData!$E$2:$E$1048576,"Expense",MasterData!$J$2:$J$1048576,TRUE))/($N$2) | D6: =(SUMIFS(MasterData!$L$2:$L$1048576,MasterData!$E$2:$E$1048576,"Savings",MasterData!$J$2:$J$1048576,TRUE))/($N$2) | E6: =B6-C6
B7: =$F$2 | C7: =$F$2 | D7: =$F$2 | E7: =$F$2
A9: 📅 Selected Period | H9: 🏷 Expenses by Category
A10: Income | B10: =(IF($D$2="",SUMIFS(MasterData!$L$2:$L$1048576,MasterData!$E$2:$E$1048576,"Income",MasterData!$B$2:$B$1048576,$B$2,MasterData!$J$2:$J$1048576,TRUE),SUMIFS(MasterData!$L$2:$L$1048576,MasterData!$E$2:$E$1048576,"Income",MasterData!$B$2:$B$1048576,$B$2,MasterData!$C$2:$C$1048576,$D$2,MasterData!$J$2:$J$1048576,TRUE)))/($N$2) | H10: Category | I10: Budget | J10: Actual | K10: Variance | L10: Var %
A11: Expenses | B11: =(IF($D$2="",SUMIFS(MasterData!$L$2:$L$1048576,MasterData!$E$2:$E$1048576,"Expense",MasterData!$B$2:$B$1048576,$B$2,MasterData!$J$2:$J$1048576,TRUE),SUMIFS(MasterData!$L$2:$L$1048576,MasterData!$E$2:$E$1048576,"Expense",MasterData!$B$2:$B$1048576,$B$2,MasterData!$C$2:$C$1048576,$D$2,MasterData!$J$2:$J$1048576,TRUE)))/($N$2) | H11: Groceries | I11: =IFERROR(VLOOKUP(H11,Lists!$C$2:$D$1048576,2,0),0)/$N$2 | J11: =(IF($D$2="",SUMIFS(MasterData!$L$2:$L$1048576,MasterData!$F$2:$F$1048576,H11,MasterData!$B$2:$B$1048576,$B$2,MasterData!$J$2:$J$1048576,TRUE),SUMIFS(MasterData!$L$2:$L$1048576,MasterData!$F$2:$F$1048576,H11,MasterData!$B$2:$B$1048576,$B$2,MasterData!$C$2:$C$1048576,$D$2,MasterData!$J$2:$J$1048576,TRUE)))/($N$2) | K11: =I11-J11 | L11: =IF(I11=0,"",K11/I11)
A12: Savings | B12: =(IF($D$2="",SUMIFS(MasterData!$L$2:$L$1048576,MasterData!$E$2:$E$1048576,"Savings",MasterData!$B$2:$B$1048576,$B$2,MasterData!$J$2:$J$1048576,TRUE),SUMIFS(MasterData!$L$2:$L$1048576,MasterData!$E$2:$E$1048576,"Savings",MasterData!$B$2:$B$1048576,$B$2,MasterData!$C$2:$C$1048576,$D$2,MasterData!$J$2:$J$1048576,TRUE)))/($N$2) | H12: Housing | I12: =IFERROR(VLOOKUP(H12,Lists!$C$2:$D$1048576,2,0),0)/$N$2 | J12: =(IF($D$2="",SUMIFS(MasterData!$L$2:$L$1048576,MasterData!$F$2:$F$1048576,H12,MasterData!$B$2:$B$1048576,$B$2,MasterData!$J$2:$J$1048576,TRUE),SUMIFS(MasterData!$L$2:$L$1048576,MasterData!$F$2:$F$1048576,H12,MasterData!$B$2:$B$1048576,$B$2,MasterData!$C$2:$C$1048576,$D$2,MasterData!$J$2:$J$1048576,TRUE)))/($N$2) | K12: =I12-J12 | L12: =IF(I12=0,"",K12/I12)
A13: Net (Income−Exp−Sav) | B13: =B10-B11-B12 | H13: Transport | I13: =IFERROR(VLOOKUP(H13,Lists!$C$2:$D$1048576,2,0),0)/$N$2 | J13: =(IF($D$2="",SUMIFS(MasterData!$L$2:$L$1048576,MasterData!$F$2:$F$1048576,H13,MasterData!$B$2:$B$1048576,$B$2,MasterData!$J$2:$J$1048576,TRUE),SUMIFS(MasterData!$L$2:$L$1048576,MasterData!$F$2:$F$1048576,H13,MasterData!$B$2:$B$1048576,$B$2,MasterData!$C$2:$C$1048576,$D$2,MasterData!$J$2:$J$1048576,TRUE)))/($N$2) | K13: =I13-J13 | L13: =IF(I13=0,"",K13/I13)
A14: Savings Rate % | B14: =IF(B10=0,0,B12/B10) | H14: Utilities | I14: =IFERROR(VLOOKUP(H14,Lists!$C$2:$D$1048576,2,0),0)/$N$2 | J14: =(IF($D$2="",SUMIFS(MasterData!$L$2:$L$1048576,MasterData!$F$2:$F$1048576,H14,MasterData!$B$2:$B$1048576,$B$2,MasterData!$J$2:$J$1048576,TRUE),SUMIFS(MasterData!$L$2:$L$1048576,MasterData!$F$2:$F$1048576,H14,MasterData!$B$2:$B$1048576,$B$2,MasterData!$C$2:$C$1048576,$D$2,MasterData!$J$2:$J$1048576,TRUE)))/($N$2) | K14: =I14-J14 | L14: =IF(I14=0,"",K14/I14)
A15: ⚠ Check | B15: =IF(ROUND(B13,0)=0,"✓ Balanced",IF(ROUND(B13,0)>0,"Unlogged: "&ROUND(B13,0)&" "&$F$2,"Overreported: "&ABS(ROUND(B13,0))&" "&$F$2)) | H15: Healthcare | I15: =IFERROR(VLOOKUP(H15,Lists!$C$2:$D$1048576,2,0),0)/$N$2 | J15: =(IF($D$2="",SUMIFS(MasterData!$L$2:$L$1048576,MasterData!$F$2:$F$1048576,H15,MasterData!$B$2:$B$1048576,$B$2,MasterData!$J$2:$J$1048576,TRUE),SUMIFS(MasterData!$L$2:$L$1048576,MasterData!$F$2:$F$1048576,H15,MasterData!$B$2:$B$1048576,$B$2,MasterData!$C$2:$C$1048576,$D$2,MasterData!$J$2:$J$1048576,TRUE)))/($N$2) | K15: =I15-J15 | L15: =IF(I15=0,"",K15/I15)
H16: Entertainment | I16: =IFERROR(VLOOKUP(H16,Lists!$C$2:$D$1048576,2,0),0)/$N$2 | J16: =(IF($D$2="",SUMIFS(MasterData!$L$2:$L$1048576,MasterData!$F$2:$F$1048576,H16,MasterData!$B$2:$B$1048576,$B$2,MasterData!$J$2:$J$1048576,TRUE),SUMIFS(MasterData!$L$2:$L$1048576,MasterData!$F$2:$F$1048576,H16,MasterData!$B$2:$B$1048576,$B$2,MasterData!$C$2:$C$1048576,$D$2,MasterData!$J$2:$J$1048576,TRUE)))/($N$2) | K16: =I16-J16 | L16: =IF(I16=0,"",K16/I16)
H17: Travel | I17: =IFERROR(VLOOKUP(H17,Lists!$C$2:$D$1048576,2,0),0)/$N$2 | J17: =(IF($D$2="",SUMIFS(MasterData!$L$2:$L$1048576,MasterData!$F$2:$F$1048576,H17,MasterData!$B$2:$B$1048576,$B$2,MasterData!$J$2:$J$1048576,TRUE),SUMIFS(MasterData!$L$2:$L$1048576,MasterData!$F$2:$F$1048576,H17,MasterData!$B$2:$B$1048576,$B$2,MasterData!$C$2:$C$1048576,$D$2,MasterData!$J$2:$J$1048576,TRUE)))/($N$2) | K17: =I17-J17 | L17: =IF(I17=0,"",K17/I17)
H18: Children | I18: =IFERROR(VLOOKUP(H18,Lists!$C$2:$D$1048576,2,0),0)/$N$2 | J18: =(IF($D$2="",SUMIFS(MasterData!$L$2:$L$1048576,MasterData!$F$2:$F$1048576,H18,MasterData!$B$2:$B$1048576,$B$2,MasterData!$J$2:$J$1048576,TRUE),SUMIFS(MasterData!$L$2:$L$1048576,MasterData!$F$2:$F$1048576,H18,MasterData!$B$2:$B$1048576,$B$2,MasterData!$C$2:$C$1048576,$D$2,MasterData!$J$2:$J$1048576,TRUE)))/($N$2) | K18: =I18-J18 | L18: =IF(I18=0,"",K18/I18)
A19: 🎯 Savings Goals | H19: Personal | I19: =IFERROR(VLOOKUP(H19,Lists!$C$2:$D$1048576,2,0),0)/$N$2 | J19: =(IF($D$2="",SUMIFS(MasterData!$L$2:$L$1048576,MasterData!$F$2:$F$1048576,H19,MasterData!$B$2:$B$1048576,$B$2,MasterData!$J$2:$J$1048576,TRUE),SUMIFS(MasterData!$L$2:$L$1048576,MasterData!$F$2:$F$1048576,H19,MasterData!$B$2:$B$1048576,$B$2,MasterData!$C$2:$C$1048576,$D$2,MasterData!$J$2:$J$1048576,TRUE)))/($N$2) | K19: =I19-J19 | L19: =IF(I19=0,"",K19/I19)
A20: Goal | B20: Alloc % | C20: Allocated | D20: Target (PLN) | E20: Still Needed | F20: Progress | H20: Shopping | I20: =IFERROR(VLOOKUP(H20,Lists!$C$2:$D$1048576,2,0),0)/$N$2 | J20: =(IF($D$2="",SUMIFS(MasterData!$L$2:$L$1048576,MasterData!$F$2:$F$1048576,H20,MasterData!$B$2:$B$1048576,$B$2,MasterData!$J$2:$J$1048576,TRUE),SUMIFS(MasterData!$L$2:$L$1048576,MasterData!$F$2:$F$1048576,H20,MasterData!$B$2:$B$1048576,$B$2,MasterData!$C$2:$C$1048576,$D$2,MasterData!$J$2:$J$1048576,TRUE)))/($N$2) | K20: =I20-J20 | L20: =IF(I20=0,"",K20/I20)
A21: =IF(Lists!$M2="","",Lists!$M2) | B21: =IF(Lists!$M2="","",Lists!$N2) | C21: =IF(Lists!$M2="","",IFERROR(MIN(Lists!$O2/$N$2, $D$6*Lists!$N2),0)) | D21: =IF(Lists!$M2="","",IFERROR(Lists!$O2/$N$2,0)) | E21: =IF(Lists!$M2="","",IFERROR(MAX(0,Lists!$O2/$N$2-MIN(Lists!$O2/$N$2,$D$6*Lists!$N2)),0)) | F21: =IF(OR(Lists!$M2="",Lists!$O2=0),"",IFERROR(MIN(1,MIN(Lists!$O2/$N$2,$D$6*Lists!$N2)/(Lists!$O2/$N$2)),0)) | H21: Insurance | I21: =IFERROR(VLOOKUP(H21,Lists!$C$2:$D$1048576,2,0),0)/$N$2 | J21: =(IF($D$2="",SUMIFS(MasterData!$L$2:$L$1048576,MasterData!$F$2:$F$1048576,H21,MasterData!$B$2:$B$1048576,$B$2,MasterData!$J$2:$J$1048576,TRUE),SUMIFS(MasterData!$L$2:$L$1048576,MasterData!$F$2:$F$1048576,H21,MasterData!$B$2:$B$1048576,$B$2,MasterData!$C$2:$C$1048576,$D$2,MasterData!$J$2:$J$1048576,TRUE)))/($N$2) | K21: =I21-J21 | L21: =IF(I21=0,"",K21/I21)
A22: =IF(Lists!$M3="","",Lists!$M3) | B22: =IF(Lists!$M3="","",Lists!$N3) | C22: =IF(Lists!$M3="","",IFERROR(MIN(Lists!$O3/$N$2, $D$6*Lists!$N3),0)) | D22: =IF(Lists!$M3="","",IFERROR(Lists!$O3/$N$2,0)) | E22: =IF(Lists!$M3="","",IFERROR(MAX(0,Lists!$O3/$N$2-MIN(Lists!$O3/$N$2,$D$6*Lists!$N3)),0)) | F22: =IF(OR(Lists!$M3="",Lists!$O3=0),"",IFERROR(MIN(1,MIN(Lists!$O3/$N$2,$D$6*Lists!$N3)/(Lists!$O3/$N$2)),0)) | H22: Loan | I22: =IFERROR(VLOOKUP(H22,Lists!$C$2:$D$1048576,2,0),0)/$N$2 | J22: =(IF($D$2="",SUMIFS(MasterData!$L$2:$L$1048576,MasterData!$F$2:$F$1048576,H22,MasterData!$B$2:$B$1048576,$B$2,MasterData!$J$2:$J$1048576,TRUE),SUMIFS(MasterData!$L$2:$L$1048576,MasterData!$F$2:$F$1048576,H22,MasterData!$B$2:$B$1048576,$B$2,MasterData!$C$2:$C$1048576,$D$2,MasterData!$J$2:$J$1048576,TRUE)))/($N$2) | K22: =I22-J22 | L22: =IF(I22=0,"",K22/I22)
A23: =IF(Lists!$M4="","",Lists!$M4) | B23: =IF(Lists!$M4="","",Lists!$N4) | C23: =IF(Lists!$M4="","",IFERROR(MIN(Lists!$O4/$N$2, $D$6*Lists!$N4),0)) | D23: =IF(Lists!$M4="","",IFERROR(Lists!$O4/$N$2,0)) | E23: =IF(Lists!$M4="","",IFERROR(MAX(0,Lists!$O4/$N$2-MIN(Lists!$O4/$N$2,$D$6*Lists!$N4)),0)) | F23: =IF(OR(Lists!$M4="",Lists!$O4=0),"",IFERROR(MIN(1,MIN(Lists!$O4/$N$2,$D$6*Lists!$N4)/(Lists!$O4/$N$2)),0)) | H23: Investment | I23: =IFERROR(VLOOKUP(H23,Lists!$C$2:$D$1048576,2,0),0)/$N$2 | J23: =(IF($D$2="",SUMIFS(MasterData!$L$2:$L$1048576,MasterData!$F$2:$F$1048576,H23,MasterData!$B$2:$B$1048576,$B$2,MasterData!$J$2:$J$1048576,TRUE),SUMIFS(MasterData!$L$2:$L$1048576,MasterData!$F$2:$F$1048576,H23,MasterData!$B$2:$B$1048576,$B$2,MasterData!$C$2:$C$1048576,$D$2,MasterData!$J$2:$J$1048576,TRUE)))/($N$2) | K23: =I23-J23 | L23: =IF(I23=0,"",K23/I23)
A24: =IF(Lists!$M5="","",Lists!$M5) | B24: =IF(Lists!$M5="","",Lists!$N5) | C24: =IF(Lists!$M5="","",IFERROR(MIN(Lists!$O5/$N$2, $D$6*Lists!$N5),0)) | D24: =IF(Lists!$M5="","",IFERROR(Lists!$O5/$N$2,0)) | E24: =IF(Lists!$M5="","",IFERROR(MAX(0,Lists!$O5/$N$2-MIN(Lists!$O5/$N$2,$D$6*Lists!$N5)),0)) | F24: =IF(OR(Lists!$M5="",Lists!$O5=0),"",IFERROR(MIN(1,MIN(Lists!$O5/$N$2,$D$6*Lists!$N5)/(Lists!$O5/$N$2)),0)) | H24: Government | I24: =IFERROR(VLOOKUP(H24,Lists!$C$2:$D$1048576,2,0),0)/$N$2 | J24: =(IF($D$2="",SUMIFS(MasterData!$L$2:$L$1048576,MasterData!$F$2:$F$1048576,H24,MasterData!$B$2:$B$1048576,$B$2,MasterData!$J$2:$J$1048576,TRUE),SUMIFS(MasterData!$L$2:$L$1048576,MasterData!$F$2:$F$1048576,H24,MasterData!$B$2:$B$1048576,$B$2,MasterData!$C$2:$C$1048576,$D$2,MasterData!$J$2:$J$1048576,TRUE)))/($N$2) | K24: =I24-J24 | L24: =IF(I24=0,"",K24/I24)
A25: =IF(Lists!$M6="","",Lists!$M6) | B25: =IF(Lists!$M6="","",Lists!$N6) | C25: =IF(Lists!$M6="","",IFERROR(MIN(Lists!$O6/$N$2, $D$6*Lists!$N6),0)) | D25: =IF(Lists!$M6="","",IFERROR(Lists!$O6/$N$2,0)) | E25: =IF(Lists!$M6="","",IFERROR(MAX(0,Lists!$O6/$N$2-MIN(Lists!$O6/$N$2,$D$6*Lists!$N6)),0)) | F25: =IF(OR(Lists!$M6="",Lists!$O6=0),"",IFERROR(MIN(1,MIN(Lists!$O6/$N$2,$D$6*Lists!$N6)/(Lists!$O6/$N$2)),0)) | H25: Education | I25: =IFERROR(VLOOKUP(H25,Lists!$C$2:$D$1048576,2,0),0)/$N$2 | J25: =(IF($D$2="",SUMIFS(MasterData!$L$2:$L$1048576,MasterData!$F$2:$F$1048576,H25,MasterData!$B$2:$B$1048576,$B$2,MasterData!$J$2:$J$1048576,TRUE),SUMIFS(MasterData!$L$2:$L$1048576,MasterData!$F$2:$F$1048576,H25,MasterData!$B$2:$B$1048576,$B$2,MasterData!$C$2:$C$1048576,$D$2,MasterData!$J$2:$J$1048576,TRUE)))/($N$2) | K25: =I25-J25 | L25: =IF(I25=0,"",K25/I25)
A26: =IF(Lists!$M7="","",Lists!$M7) | B26: =IF(Lists!$M7="","",Lists!$N7) | C26: =IF(Lists!$M7="","",IFERROR(MIN(Lists!$O7/$N$2, $D$6*Lists!$N7),0)) | D26: =IF(Lists!$M7="","",IFERROR(Lists!$O7/$N$2,0)) | E26: =IF(Lists!$M7="","",IFERROR(MAX(0,Lists!$O7/$N$2-MIN(Lists!$O7/$N$2,$D$6*Lists!$N7)),0)) | F26: =IF(OR(Lists!$M7="",Lists!$O7=0),"",IFERROR(MIN(1,MIN(Lists!$O7/$N$2,$D$6*Lists!$N7)/(Lists!$O7/$N$2)),0)) | H26: Subscriptions | I26: =IFERROR(VLOOKUP(H26,Lists!$C$2:$D$1048576,2,0),0)/$N$2 | J26: =(IF($D$2="",SUMIFS(MasterData!$L$2:$L$1048576,MasterData!$F$2:$F$1048576,H26,MasterData!$B$2:$B$1048576,$B$2,MasterData!$J$2:$J$1048576,TRUE),SUMIFS(MasterData!$L$2:$L$1048576,MasterData!$F$2:$F$1048576,H26,MasterData!$B$2:$B$1048576,$B$2,MasterData!$C$2:$C$1048576,$D$2,MasterData!$J$2:$J$1048576,TRUE)))/($N$2) | K26: =I26-J26 | L26: =IF(I26=0,"",K26/I26)
A27: =IF(Lists!$M8="","",Lists!$M8) | B27: =IF(Lists!$M8="","",Lists!$N8) | C27: =IF(Lists!$M8="","",IFERROR(MIN(Lists!$O8/$N$2, $D$6*Lists!$N8),0)) | D27: =IF(Lists!$M8="","",IFERROR(Lists!$O8/$N$2,0)) | E27: =IF(Lists!$M8="","",IFERROR(MAX(0,Lists!$O8/$N$2-MIN(Lists!$O8/$N$2,$D$6*Lists!$N8)),0)) | F27: =IF(OR(Lists!$M8="",Lists!$O8=0),"",IFERROR(MIN(1,MIN(Lists!$O8/$N$2,$D$6*Lists!$N8)/(Lists!$O8/$N$2)),0)) | H27: Other | I27: =IFERROR(VLOOKUP(H27,Lists!$C$2:$D$1048576,2,0),0)/$N$2 | J27: =(IF($D$2="",SUMIFS(MasterData!$L$2:$L$1048576,MasterData!$F$2:$F$1048576,H27,MasterData!$B$2:$B$1048576,$B$2,MasterData!$J$2:$J$1048576,TRUE),SUMIFS(MasterData!$L$2:$L$1048576,MasterData!$F$2:$F$1048576,H27,MasterData!$B$2:$B$1048576,$B$2,MasterData!$C$2:$C$1048576,$D$2,MasterData!$J$2:$J$1048576,TRUE)))/($N$2) | K27: =I27-J27 | L27: =IF(I27=0,"",K27/I27)
A28: =IF(Lists!$M9="","",Lists!$M9) | B28: =IF(Lists!$M9="","",Lists!$N9) | C28: =IF(Lists!$M9="","",IFERROR(MIN(Lists!$O9/$N$2, $D$6*Lists!$N9),0)) | D28: =IF(Lists!$M9="","",IFERROR(Lists!$O9/$N$2,0)) | E28: =IF(Lists!$M9="","",IFERROR(MAX(0,Lists!$O9/$N$2-MIN(Lists!$O9/$N$2,$D$6*Lists!$N9)),0)) | F28: =IF(OR(Lists!$M9="",Lists!$O9=0),"",IFERROR(MIN(1,MIN(Lists!$O9/$N$2,$D$6*Lists!$N9)/(Lists!$O9/$N$2)),0)) | H28: TOTAL | I28: =SUM(I11:I27) | J28: =SUM(J11:J27) | K28: =SUM(K11:K27)
A29: =IF(Lists!$M10="","",Lists!$M10) | B29: =IF(Lists!$M10="","",Lists!$N10) | C29: =IF(Lists!$M10="","",IFERROR(MIN(Lists!$O10/$N$2, $D$6*Lists!$N10),0)) | D29: =IF(Lists!$M10="","",IFERROR(Lists!$O10/$N$2,0)) | E29: =IF(Lists!$M10="","",IFERROR(MAX(0,Lists!$O10/$N$2-MIN(Lists!$O10/$N$2,$D$6*Lists!$N10)),0)) | F29: =IF(OR(Lists!$M10="",Lists!$O10=0),"",IFERROR(MIN(1,MIN(Lists!$O10/$N$2,$D$6*Lists!$N10)/(Lists!$O10/$N$2)),0))
A30: =IF(Lists!$M11="","",Lists!$M11) | B30: =IF(Lists!$M11="","",Lists!$N11) | C30: =IF(Lists!$M11="","",IFERROR(MIN(Lists!$O11/$N$2, $D$6*Lists!$N11),0)) | D30: =IF(Lists!$M11="","",IFERROR(Lists!$O11/$N$2,0)) | E30: =IF(Lists!$M11="","",IFERROR(MAX(0,Lists!$O11/$N$2-MIN(Lists!$O11/$N$2,$D$6*Lists!$N11)),0)) | F30: =IF(OR(Lists!$M11="",Lists!$O11=0),"",IFERROR(MIN(1,MIN(Lists!$O11/$N$2,$D$6*Lists!$N11)/(Lists!$O11/$N$2)),0))
A31: =IF(Lists!$M12="","",Lists!$M12) | B31: =IF(Lists!$M12="","",Lists!$N12) | C31: =IF(Lists!$M12="","",IFERROR(MIN(Lists!$O12/$N$2, $D$6*Lists!$N12),0)) | D31: =IF(Lists!$M12="","",IFERROR(Lists!$O12/$N$2,0)) | E31: =IF(Lists!$M12="","",IFERROR(MAX(0,Lists!$O12/$N$2-MIN(Lists!$O12/$N$2,$D$6*Lists!$N12)),0)) | F31: =IF(OR(Lists!$M12="",Lists!$O12=0),"",IFERROR(MIN(1,MIN(Lists!$O12/$N$2,$D$6*Lists!$N12)/(Lists!$O12/$N$2)),0))
A32: =IF(Lists!$M13="","",Lists!$M13) | B32: =IF(Lists!$M13="","",Lists!$N13) | C32: =IF(Lists!$M13="","",IFERROR(MIN(Lists!$O13/$N$2, $D$6*Lists!$N13),0)) | D32: =IF(Lists!$M13="","",IFERROR(Lists!$O13/$N$2,0)) | E32: =IF(Lists!$M13="","",IFERROR(MAX(0,Lists!$O13/$N$2-MIN(Lists!$O13/$N$2,$D$6*Lists!$N13)),0)) | F32: =IF(OR(Lists!$M13="",Lists!$O13=0),"",IFERROR(MIN(1,MIN(Lists!$O13/$N$2,$D$6*Lists!$N13)/(Lists!$O13/$N$2)),0))
A33: =IF(Lists!$M14="","",Lists!$M14) | B33: =IF(Lists!$M14="","",Lists!$N14) | C33: =IF(Lists!$M14="","",IFERROR(MIN(Lists!$O14/$N$2, $D$6*Lists!$N14),0)) | D33: =IF(Lists!$M14="","",IFERROR(Lists!$O14/$N$2,0)) | E33: =IF(Lists!$M14="","",IFERROR(MAX(0,Lists!$O14/$N$2-MIN(Lists!$O14/$N$2,$D$6*Lists!$N14)),0)) | F33: =IF(OR(Lists!$M14="",Lists!$O14=0),"",IFERROR(MIN(1,MIN(Lists!$O14/$N$2,$D$6*Lists!$N14)/(Lists!$O14/$N$2)),0))
A34: =IF(Lists!$M15="","",Lists!$M15) | B34: =IF(Lists!$M15="","",Lists!$N15) | C34: =IF(Lists!$M15="","",IFERROR(MIN(Lists!$O15/$N$2, $D$6*Lists!$N15),0)) | D34: =IF(Lists!$M15="","",IFERROR(Lists!$O15/$N$2,0)) | E34: =IF(Lists!$M15="","",IFERROR(MAX(0,Lists!$O15/$N$2-MIN(Lists!$O15/$N$2,$D$6*Lists!$N15)),0)) | F34: =IF(OR(Lists!$M15="",Lists!$O15=0),"",IFERROR(MIN(1,MIN(Lists!$O15/$N$2,$D$6*Lists!$N15)/(Lists!$O15/$N$2)),0))
A35: =IF(Lists!$M16="","",Lists!$M16) | B35: =IF(Lists!$M16="","",Lists!$N16) | C35: =IF(Lists!$M16="","",IFERROR(MIN(Lists!$O16/$N$2, $D$6*Lists!$N16),0)) | D35: =IF(Lists!$M16="","",IFERROR(Lists!$O16/$N$2,0)) | E35: =IF(Lists!$M16="","",IFERROR(MAX(0,Lists!$O16/$N$2-MIN(Lists!$O16/$N$2,$D$6*Lists!$N16)),0)) | F35: =IF(OR(Lists!$M16="",Lists!$O16=0),"",IFERROR(MIN(1,MIN(Lists!$O16/$N$2,$D$6*Lists!$N16)/(Lists!$O16/$N$2)),0))
A36: TOTAL | C36: =IFERROR(SUM(C21:C35),"") | D36: =IFERROR(SUM(D21:D35),"") | E36: =IFERROR(SUM(E21:E35),"")

Sheet Cycles
A1: StartDate | B1: Label
